<?xml version="1.0" ?>

<!-- Author | Shalman -->
<robot name="panda" xmlns:xacro="http://www.ros.org/wiki/xacro">
    <link name="world"></link>

    <joint name="base_joint" type="fixed">
        <origin xyz="0 0 0" rpy="0 0 0"/>
        <parent link="world"/>
        <child link="panda_link0"/>        
    </joint>

    <link name="panda_link0">
        <inertial>
            <mass value="2.92"/>
            <origin rpy="0 0 0" xyz="-0.025566 -2.88e-05 0.057332"/>
            <inertia ixx="0.00782229414331" ixy="-1.56191622996e-05" ixz="-0.00126005738123" iyy="0.0109027971813" iyz="1.08233858202e-05" izz="0.0102355503949"/>
        </inertial>
        <visual>
            <geometry>
                <mesh filename="file://$(find cam_sim_pkg)/meshes/visual/link0.dae" />
            </geometry>
        </visual>
        <visual>
            <geometry>
                <mesh filename="file://$(find cam_sim_pkg)/meshes/visual/link0.dae" />
            </geometry>
        </visual>
    </link>
    <link name="panda_link1">
        <inertial>
            <mass value="2.74"/>
            <origin rpy="0 0 0" xyz="0 -0.0324958 -0.0675818"/>
            <inertia ixx="0.0180416958283" ixy="0.0" ixz="0.0" iyy="0.0159136071891" iyz="0.0046758424612" izz="0.00620690827127"/>
        </inertial>
        <visual>
            <geometry>
                <mesh filename="file://$(find cam_sim_pkg)/meshes/visual/link1.dae" />
            </geometry>
        </visual>
        <visual>
            <geometry>
                <mesh filename="file://$(find cam_sim_pkg)/meshes/visual/link1.dae" />
            </geometry>
        </visual>
    </link>
    <joint name="panda_joint1" type="revolute">
        <safety_controller k_position="100.0" k_velocity="40.0" soft_lower_limit="-2.8973" soft_upper_limit="2.8973" />
        <origin rpy="0 0 0" xyz="0 0 0.333" />
        <parent link="panda_link0" />
        <child link="panda_link1" />
        <axis xyz="0 0 1" />
        <limit effort="87" lower="-2.9671" upper="2.9671" velocity="2.3925" />
        <dynamics damping="5000.0" friction="5000.0"/>
    </joint>
    <link name="panda_link2">
        <inertial>
            <mass value="2.74"/>
            <origin rpy="0 0 0" xyz="0 -0.06861 0.0322285"/>
            <inertia ixx="0.0182856182281" ixy="0.0" ixz="0.0" iyy="0.00621358421175" iyz="-0.00472844221905" izz="0.0161514346309"/>
        </inertial>
        <visual>
            <geometry>
                <mesh filename="file://$(find cam_sim_pkg)/meshes/visual/link2.dae" />
            </geometry>
        </visual>
        <visual>
            <geometry>
                <mesh filename="file://$(find cam_sim_pkg)/meshes/visual/link2.dae" />
            </geometry>
        </visual>
    </link>
    <joint name="panda_joint2" type="revolute">
        <safety_controller k_position="100.0" k_velocity="40.0" soft_lower_limit="-1.7628" soft_upper_limit="1.7628" />
        <origin rpy="-1.57079632679 0 0" xyz="0 0 0" />
        <parent link="panda_link1" />
        <child link="panda_link2" />
        <axis xyz="0 0 1" />
        <limit effort="87" lower="-1.8326" upper="1.8326" velocity="2.3925" />
        <dynamics damping="5000.0" friction="5000.0"/>
    </joint>
    <link name="panda_link3">
        <inertial>
            <mass value="2.38"/>
            <origin rpy="0 0 0" xyz="0.0469893 0.0316374 -0.031704"/>
            <inertia ixx="0.00771376630908" ixy="-0.00248490625138" ixz="-0.00332147581033" iyy="0.00989108008727" iyz="-0.00217796151484" izz="0.00811723558464"/>
        </inertial>
        <visual>
            <geometry>
                <mesh filename="file://$(find cam_sim_pkg)/meshes/visual/link3.dae" />
            </geometry>
        </visual>
        <visual>
            <geometry>
                <mesh filename="file://$(find cam_sim_pkg)/meshes/visual/link3.dae" />
            </geometry>
        </visual>
    </link>
    <joint name="panda_joint3" type="revolute">
        <safety_controller k_position="100.0" k_velocity="40.0" soft_lower_limit="-2.8973" soft_upper_limit="2.8973" />
        <origin rpy="1.57079632679 0 0" xyz="0 -0.316 0" />
        <parent link="panda_link2" />
        <child link="panda_link3" />
        <axis xyz="0 0 1" />
        <limit effort="87" lower="-2.9671" upper="2.9671" velocity="2.3925" />
        <dynamics damping="5000.0" friction="5000.0"/>
    </joint>
    <link name="panda_link4">
        <inertial>
            <mass value="2.38"/>
            <origin rpy="0 0 0" xyz="-0.0360446 0.0336853 0.031882"/>
            <inertia ixx="0.00799663881132" ixy="0.00347095570217" ixz="-0.00241222942995" iyy="0.00825390705278" iyz="0.00235774044121" izz="0.0102515004345"/>
        </inertial>
        <visual>
            <geometry>
                <mesh filename="file://$(find cam_sim_pkg)/meshes/visual/link4.dae" />
            </geometry>
        </visual>
        <visual>
            <geometry>
                <mesh filename="file://$(find cam_sim_pkg)/meshes/visual/link4.dae" />
            </geometry>
        </visual>
    </link>
    <joint name="panda_joint4" type="revolute">
        <safety_controller k_position="100.0" k_velocity="40.0" soft_lower_limit="-3.0718" soft_upper_limit="0.0175" />
        <origin rpy="1.57079632679 0 0" xyz="0.0825 0 0" />
        <parent link="panda_link3" />
        <child link="panda_link4" />
        <axis xyz="0 0 1" />
        <limit effort="87" lower="-3.1416" upper="0.0873" velocity="2.3925" />
        <dynamics damping="5000.0" friction="5000.0"/>
    </joint>
    <link name="panda_link5">
        <inertial>
            <mass value="2.74"/>
            <origin rpy="0 0 0" xyz="0 0.0610427 -0.104176"/>
            <inertia ixx="0.030371374513" ixy="6.50283587108e-07" ixz="-1.05129179916e-05" iyy="0.0288752887402" iyz="-0.00775653445787" izz="0.00444134056164"/>
        </inertial>
        <visual>
            <geometry>
                <mesh filename="file://$(find cam_sim_pkg)/meshes/visual/link5.dae" />
            </geometry>
        </visual>
        <visual>
            <geometry>
                <mesh filename="file://$(find cam_sim_pkg)/meshes/visual/link5.dae" />
            </geometry>
        </visual>
    </link>
    <joint name="panda_joint5" type="revolute">
        <safety_controller k_position="100.0" k_velocity="40.0" soft_lower_limit="-2.8973" soft_upper_limit="2.8973" />
        <origin rpy="-1.57079632679 0 0" xyz="-0.0825 0.384 0" />
        <parent link="panda_link4" />
        <child link="panda_link5" />
        <axis xyz="0 0 1" />
        <limit effort="12" lower="-2.9671" upper="2.9671" velocity="2.8710" />
        <dynamics damping="5000.0" friction="5000.0"/>
    </joint>
    <link name="panda_link6">
        <inertial>
            <mass value="1.55"/>
            <origin rpy="0 0 0" xyz="0.0510509 0.009108 0.0106343"/>
            <inertia ixx="0.00303336450376" ixy="-0.000437276865508" ixz="0.000629257294877" iyy="0.00404479911567" iyz="0.000130472021025" izz="0.00558234286039"/>
        </inertial>
        <visual>
            <geometry>
                <mesh filename="file://$(find cam_sim_pkg)/meshes/visual/link6.dae" />
            </geometry>
        </visual>
        <visual>
            <geometry>
                <mesh filename="file://$(find cam_sim_pkg)/meshes/visual/link6.dae" />
            </geometry>
        </visual>
    </link>
    <joint name="panda_joint6" type="revolute">
        <safety_controller k_position="100.0" k_velocity="40.0" soft_lower_limit="-0.0175" soft_upper_limit="3.7525" />
        <origin rpy="1.57079632679 0 0" xyz="0 0 0" />
        <parent link="panda_link5" />
        <child link="panda_link6" />
        <axis xyz="0 0 1" />
        <limit effort="12" lower="-0.0873" upper="3.8223" velocity="2.8710" />
        <dynamics damping="5000.0" friction="5000.0"/>
    </joint>
    <link name="panda_link7">
        <inertial>
            <mass value="0.54"/>
            <origin rpy="0 0 0" xyz="0.0109695 0.0107965 0.0650411"/>
            <inertia ixx="0.000888868887021" ixy="-0.00012239074652" ixz="3.98699829666e-05" iyy="0.000888001373233" iyz="-9.33825115206e-05" izz="0.0007176834609"/>
        </inertial>
        <visual>
            <geometry>
                <mesh filename="file://$(find cam_sim_pkg)/meshes/visual/link7.dae" />
            </geometry>
        </visual>
        <visual>
            <geometry>
                <mesh filename="file://$(find cam_sim_pkg)/meshes/visual/link7.dae" />
            </geometry>
        </visual>
    </link>
    <joint name="panda_joint7" type="revolute">
        <safety_controller k_position="100.0" k_velocity="40.0" soft_lower_limit="-2.8973" soft_upper_limit="2.8973" />
        <origin rpy="1.57079632679 0 0" xyz="0.088 0 0" />
        <parent link="panda_link6" />
        <child link="panda_link7" />
        <axis xyz="0 0 1" />
        <limit effort="12" lower="-2.9671" upper="2.9671" velocity="2.8710" />
        <dynamics damping="1000.0" friction="1000.0"/>
    </joint>
    <link name="panda_link8" />
    <joint name="panda_joint8" type="fixed">
        <origin rpy="0 0 0" xyz="0 0 0.107" />
        <parent link="panda_link7" />
        <child link="panda_link8" />
        <axis xyz="0 0 0" />
    </joint>
    <joint name="panda_hand_joint" type="fixed">
        <parent link="panda_link8" />
        <child link="panda_hand" />
        <origin rpy="0 0 -0.785398163397" xyz="0 0 0" />
    </joint>
    <link name="panda_hand">
        <inertial>
            <mass value="0.73"/>
            <origin rpy="0 0 0" xyz="0 0.0015244 0.0275912"/>
            <inertia ixx="0.00278560230025" ixy="0.0" ixz="0.0" iyy="0.000400033405336" iyz="0.0" izz="0.00256378041832"/>
        </inertial>
        <visual>
            <geometry>
                <mesh filename="file://$(find cam_sim_pkg)/meshes/visual/hand.dae" />
            </geometry>
        </visual>
        <visual>
            <geometry>
                <mesh filename="file://$(find cam_sim_pkg)/meshes/visual/hand.dae" />
            </geometry>
        </visual>
    </link>
    <link name="panda_leftfinger">
        <inertial>
            <mass value="0.1"/>
            <origin rpy="0 0 0" xyz="0 0.0145644 0.0227941"/>
            <inertia ixx="3.01220925051e-05" ixy="0.0" ixz="0.0" iyy="2.95873808038e-05" iyz="0.0" izz="6.95125211657e-06"/>
        </inertial>
        <visual>
            <geometry>
                <mesh filename="file://$(find cam_sim_pkg)/meshes/visual/finger.dae" />
            </geometry>
        </visual>
        <visual>
            <geometry>
                <mesh filename="file://$(find cam_sim_pkg)/meshes/visual/finger.dae" />
            </geometry>
        </visual>
    </link>
    <link name="panda_rightfinger">
        <inertial>
            <mass value="0.1"/>
            <origin rpy="0 0 3.14159265359" xyz="0 0.0145644 0.0227941"/>
            <inertia ixx="3.01220925051e-05" ixy="0.0" ixz="0.0" iyy="2.95873808038e-05" iyz="0.0" izz="6.95125211657e-06"/>
        </inertial>
        <visual>
            <origin rpy="0 0 3.14159265359" xyz="0 0 0" />
            <geometry>
                <mesh filename="file://$(find cam_sim_pkg)/meshes/visual/finger.dae" />
            </geometry>
        </visual>
        <visual>
            <origin rpy="0 0 3.14159265359" xyz="0 0 0" />
            <geometry>
                <mesh filename="file://$(find cam_sim_pkg)/meshes/visual/finger.dae" />
            </geometry>
        </visual>
    </link>
    <joint name="panda_finger_joint1" type="prismatic">
        <parent link="panda_hand" />
        <child link="panda_leftfinger" />
        <origin rpy="0 0 0" xyz="0 0 0.0584" />
        <axis xyz="0 1 0" />
        <limit effort="20" lower="0.0" upper="0.04" velocity="0.2" />
        <dynamics damping="1000.0" friction="1000.0"/>
    </joint>
    <joint name="panda_finger_joint2" type="prismatic">
        <parent link="panda_hand" />
        <child link="panda_rightfinger" />
        <origin rpy="0 0 0" xyz="0 0 0.0584" />
        <axis xyz="0 -1 0" />
        <limit effort="20" lower="0.0" upper="0.04" velocity="0.2" />
        <dynamics damping="1000.0" friction="1000.0"/>
        <mimic joint="panda_finger_joint1" />
    </joint>

    <!-- Camera Link -->
    <link name="camera_link">
        <visual>
            <!-- Visual Origin Position and Orientation -->
            <origin rpy="1.57 0 1.57" xyz="0.0 0 0.0" />
            <geometry>
            <!-- Visual Origin Position and Orientation -->
                <mesh filename="file://$(find cam_sim_pkg)/meshes/visual/camera_d435.dae" />
            </geometry>
        </visual>
        <visual>
            <!-- visual Origin Position and Orientation -->
            <origin rpy="1.57 0 1.57" xyz="0.0 0 0.0" />
            <geometry>
            <!-- visual Origin Position and Orientation -->
                <mesh filename="file://$(find cam_sim_pkg)/meshes/visual/camera_d435.dae" />
            </geometry>
        </visual>
    </link>
    
    <!-- Joint Connecting camera to panda_link0 -->
    <joint name="base_to_static_camera" type="fixed">
        <!-- Joint Origin with respect to panda_link_0 origin -->
        <origin rpy="0 2.70 0" xyz="1.0 0 1.0" />
        <!-- Parent and Child Link -->
        <parent link="panda_link0" />
        <child link="camera_link" />
    </joint>

    <!-- Import Gazebo xacro to integrate gazebo ros funtionalities -->
    <xacro:include filename="$(find PACKAGE_NAME)/urdf/(GAZEBO_XACRO_FILENAME)"/>	

</robot>